Workbook

Sheet Cover
A1: Tender rates template - FICTIONAL_CEDANT_A - T_ALPHA_2027
A3: Deadline | B3: 2026-11-05
A4: Contact | B4: synthetic contact
A5: Currency / basis | B5: AED / NET
A6: Basis statement | B6: Submit base rates only, at the reference co-pay options stated on each sheet. Co-pay, annual limit, TPA, nationality and network-option adjustments are the factor tables shown in Factor Tables (read only unless a proposed column is offered).
A7: Instructions | B7: Fill the yellow cells with annual premiums per member greater than 0. Grey cells are referred. Do not insert, delete or rename sheets, rows or columns.
A8: Template version | B8: 1 / generator ws0-1
A9: Structure hash | B9: a5cc3bbbff4544408e647e19fa833066ddb52921c093d9af3d88eaa052486296
A11: Sheet directory
A12: Existing Rates | B12: read only
A13: Factor Tables | B13: read only
A14: Add-ons | B14: read only
A15: INDIVIDUAL RGN_A | B15: fill yellow cells (3 block(s): TPA_RED, TPA_BLUE, TPA_GREEN)
A16: Terms | B16: fill

Sheet Existing Rates
A1: Existing Rates - expiring catalogue, same blocks (read only)
A2: Source: CAT_ALPHA v1. Base table values at the reference options (before factor tables).
A4: INDIVIDUAL RGN_A / TPA_RED
C5: Plan 1 | E5: Plan 2 | G5: Plan 3 | I5: Plan 4 | K5: Plan 5 | M5: Plan 6 | O5: Plan 7
C6: Male | D6: Female | E6: Male | F6: Female | G6: Male | H6: Female | I6: Male | J6: Female | K6: Male | L6: Female | M6: Male | N6: Female | O6: Male | P6: Female
B7: 0-4 | C7: 1087.11 | D7: 1054.5 | E7: 917.25 | F7: 889.73 | G7: 801.74 | H7: 777.69 | I7: 679.44 | J7: 659.06 | K7: 584.32 | L7: 566.79 | M7: 502.79 | N7: 487.7 | O7: 428.05 | P7: 415.21
B8: 5-9 | C8: 1238.72 | D8: 1201.56 | E8: 1045.17 | F8: 1013.81 | G8: 913.55 | H8: 886.15 | I8: 774.2 | J8: 750.97 | K8: 665.81 | L8: 645.84 | M8: 572.91 | N8: 555.72 | O8: 487.74 | P8: 473.11
B9: 10-14 | C9: 1432.61 | D9: 1389.64 | E9: 1208.77 | F9: 1172.51 | G9: 1056.55 | H9: 1024.86 | I9: 895.38 | J9: 868.52 | K9: 770.03 | L9: 746.93 | M9: 662.58 | N9: 642.71 | O9: 564.09 | P9: 547.17
B10: 15-19 | C10: 1669.18 | D10: 1619.11 | E10: 1408.37 | F10: 1366.12 | G10: 1231.02 | H10: 1194.09 | I10: 1043.24 | J10: 1011.94 | K10: 897.18 | L10: 870.27 | M10: 772 | N10: 748.84 | O10: 657.24 | P10: 637.52
B11: 20-24 | C11: 1948.04 | D11: 2084.4 | E11: 1643.66 | F11: 1758.71 | G11: 1436.68 | H11: 1537.25 | I11: 1217.52 | J11: 1302.75 | K11: 1047.07 | L11: 1120.37 | M11: 900.97 | N11: 964.04 | O11: 767.04 | P11: 820.73
B12: 25-29 | C12: 2269.56 | D12: 2428.43 | E12: 1914.95 | F12: 2048.99 | G12: 1673.8 | H12: 1790.97 | I12: 1418.48 | J12: 1517.77 | K12: 1219.89 | L12: 1305.28 | M12: 1049.67 | N12: 1123.15 | O12: 893.64 | P12: 956.2
B13: 30-34 | C13: 2633.38 | D13: 2817.72 | E13: 2221.92 | F13: 2377.45 | G13: 1942.12 | H13: 2078.07 | I13: 1645.86 | J13: 1761.07 | K13: 1415.44 | L13: 1514.52 | M13: 1217.94 | N13: 1303.2 | O13: 1036.89 | P13: 1109.48
B14: 35-39 | C14: 3039.68 | D14: 3252.46 | E14: 2564.73 | F14: 2744.26 | G14: 2241.76 | H14: 2398.69 | I14: 1899.8 | J14: 2032.79 | K14: 1633.83 | L14: 1748.2 | M14: 1405.85 | N14: 1504.26 | O14: 1196.87 | P14: 1280.66
B15: 40-44 | C15: 3488.65 | D15: 3732.85 | E15: 2943.55 | F15: 3149.59 | G15: 2572.88 | H15: 2752.98 | I15: 2180.4 | J15: 2333.03 | K15: 1875.15 | L15: 2006.41 | M15: 1613.5 | N15: 1726.44 | O15: 1373.65 | P15: 1469.81
B16: 45-49 | C16: 3979.9 | D16: 3860.51 | E16: 3358.04 | F16: 3257.3 | G16: 2935.18 | H16: 2847.12 | I16: 2487.44 | J16: 2412.82 | K16: 2139.2 | L16: 2075.02 | M16: 1840.71 | N16: 1785.48 | O16: 1567.09 | P16: 1520.07
B17: 50-54 | C17: 4513.83 | D17: 4378.42 | E17: 3808.54 | F17: 3694.29 | G17: 3328.95 | H17: 3229.08 | I17: 2821.14 | J17: 2736.51 | K17: 2426.18 | L17: 2353.4 | M17: 2087.65 | N17: 2025.02 | O17: 1777.32 | P17: 1724
B18: 55-59 | C18: 5090.05 | D18: 4937.35 | E18: 4294.73 | F18: 4165.89 | G18: 3753.91 | H18: 3641.29 | I18: 3181.28 | J18: 3085.84 | K18: 2735.9 | L18: 2653.82 | M18: 2354.15 | N18: 2283.52 | O18: 2004.21 | P18: 1944.08
... B20: 65-69 | C20: 6370.11 | D20: 6179.01 | E20: 5374.78 | F20: 5213.54 | G20: 4697.96 | H20: 4557.02 | I20: 3981.32 | J20: 3861.88 | K20: 3423.94 | L20: 3321.22 | M20: 2946.18 | N20: 2857.79 | O20: 2508.23 | P20: 2432.98
B21: 70+ | C21: 7897.13 | D21: 7660.21 | E21: 6663.2 | F21: 6463.3 | G21: 5824.13 | H21: 5649.41 | I21: 4935.7 | J21: 4787.63 | K21: 4244.71 | L21: 4117.36 | M21: REFER | N21: REFER | O21: REFER | P21: REFER
A24: INDIVIDUAL RGN_A / TPA_BLUE
C25: Plan 1 | E25: Plan 2 | G25: Plan 3 | I25: Plan 4 | K25: Plan 5 | M25: Plan 6 | O25: Plan 7
C26: Male | D26: Female | E26: Male | F26: Female | G26: Male | H26: Female | I26: Male | J26: Female | K26: Male | L26: Female | M26: Male | N26: Female | O26: Male | P26: Female
B27: 0-4 | C27: 1087.11 | D27: 1054.5 | E27: 917.25 | F27: 889.73 | G27: 801.74 | H27: 777.69 | I27: 679.44 | J27: 659.06 | K27: 584.32 | L27: 566.79 | M27: 502.79 | N27: 487.7 | O27: 428.05 | P27: 415.21
B28: 5-9 | C28: 1238.72 | D28: 1201.56 | E28: 1045.17 | F28: 1013.81 | G28: 913.55 | H28: 886.15 | I28: 774.2 | J28: 750.97 | K28: 665.81 | L28: 645.84 | M28: 572.91 | N28: 555.72 | O28: 487.74 | P28: 473.11
B29: 10-14 | C29: 1432.61 | D29: 1389.64 | E29: 1208.77 | F29: 1172.51 | G29: 1056.55 | H29: 1024.86 | I29: 895.38 | J29: 868.52 | K29: 770.03 | L29: 746.93 | M29: 662.58 | N29: 642.71 | O29: 564.09 | P29: 547.17
B30: 15-19 | C30: 1669.18 | D30: 1619.11 | E30: 1408.37 | F30: 1366.12 | G30: 1231.02 | H30: 1194.09 | I30: 1043.24 | J30: 1011.94 | K30: 897.18 | L30: 870.27 | M30: 772 | N30: 748.84 | O30: 657.24 | P30: 637.52
B31: 20-24 | C31: 1948.04 | D31: 2084.4 | E31: 1643.66 | F31: 1758.71 | G31: 1436.68 | H31: 1537.25 | I31: 1217.52 | J31: 1302.75 | K31: 1047.07 | L31: 1120.37 | M31: 900.97 | N31: 964.04 | O31: 767.04 | P31: 820.73
B32: 25-29 | C32: 2269.56 | D32: 2428.43 | E32: 1914.95 | F32: 2048.99 | G32: 1673.8 | H32: 1790.97 | I32: 1418.48 | J32: 1517.77 | K32: 1219.89 | L32: 1305.28 | M32: 1049.67 | N32: 1123.15 | O32: 893.64 | P32: 956.2
B33: 30-34 | C33: 2633.38 | D33: 2817.72 | E33: 2221.92 | F33: 2377.45 | G33: 1942.12 | H33: 2078.07 | I33: 1645.86 | J33: 1761.07 | K33: 1415.44 | L33: 1514.52 | M33: 1217.94 | N33: 1303.2 | O33: 1036.89 | P33: 1109.48
B34: 35-39 | C34: 3039.68 | D34: 3252.46 | E34: 2564.73 | F34: 2744.26 | G34: 2241.76 | H34: 2398.69 | I34: 1899.8 | J34: 2032.79 | K34: 1633.83 | L34: 1748.2 | M34: 1405.85 | N34: 1504.26 | O34: 1196.87 | P34: 1280.66
B35: 40-44 | C35: 3488.65 | D35: 3732.85 | E35: 2943.55 | F35: 3149.59 | G35: 2572.88 | H35: 2752.98 | I35: 2180.4 | J35: 2333.03 | K35: 1875.15 | L35: 2006.41 | M35: 1613.5 | N35: 1726.44 | O35: 1373.65 | P35: 1469.81
B36: 45-49 | C36: 3979.9 | D36: 3860.51 | E36: 3358.04 | F36: 3257.3 | G36: 2935.18 | H36: 2847.12 | I36: 2487.44 | J36: 2412.82 | K36: 2139.2 | L36: 2075.02 | M36: 1840.71 | N36: 1785.48 | O36: 1567.09 | P36: 1520.07
B37: 50-54 | C37: 4513.83 | D37: 4378.42 | E37: 3808.54 | F37: 3694.29 | G37: 3328.95 | H37: 3229.08 | I37: 2821.14 | J37: 2736.51 | K37: 2426.18 | L37: 2353.4 | M37: 2087.65 | N37: 2025.02 | O37: 1777.32 | P37: 1724
B38: 55-59 | C38: 5090.05 | D38: 4937.35 | E38: 4294.73 | F38: 4165.89 | G38: 3753.91 | H38: 3641.29 | I38: 3181.28 | J38: 3085.84 | K38: 2735.9 | L38: 2653.82 | M38: 2354.15 | N38: 2283.52 | O38: 2004.21 | P38: 1944.08
... B40: 65-69 | C40: 6370.11 | D40: 6179.01 | E40: 5374.78 | F40: 5213.54 | G40: 4697.96 | H40: 4557.02 | I40: 3981.32 | J40: 3861.88 | K40: 3423.94 | L40: 3321.22 | M40: 2946.18 | N40: 2857.79 | O40: 2508.23 | P40: 2432.98
B41: 70+ | C41: 7897.13 | D41: 7660.21 | E41: 6663.2 | F41: 6463.3 | G41: 5824.13 | H41: 5649.41 | I41: 4935.7 | J41: 4787.63 | K41: 4244.71 | L41: 4117.36 | M41: REFER | N41: REFER | O41: REFER | P41: REFER
A44: INDIVIDUAL RGN_A / TPA_GREEN
C45: Plan 1 | E45: Plan 2 | G45: Plan 3 | I45: Plan 4 | K45: Plan 5 | M45: Plan 6 | O45: Plan 7
C46: Male | D46: Female | E46: Male | F46: Female | G46: Male | H46: Female | I46: Male | J46: Female | K46: Male | L46: Female | M46: Male | N46: Female | O46: Male | P46: Female
B47: 0-4 | C47: 1087.11 | D47: 1054.5 | E47: 917.25 | F47: 889.73 | G47: 801.74 | H47: 777.69 | I47: 679.44 | J47: 659.06 | K47: 584.32 | L47: 566.79 | M47: 502.79 | N47: 487.7 | O47: 428.05 | P47: 415.21
...

Sheet Factor Tables
A1: Factor tables (read only): applied by the cedant to the submitted base rates
A3: ALPHA_IND_A / f_opdiag (copay_op_diag); reference: 0%
A4: copay_op_diag | B4: factor
A5: 0% | B5: 1
A6: 10% | B6: 0.955
A7: 20% | B7: 0.915
A8: AED25 | B8: 0.988
A10: ALPHA_IND_A / f_consult (ded_consult); reference: D30
A11: ded_consult | B11: factor
A12: D30 | B12: 1
A13: D60 | B13: 0.972
A14: NIL | B14: 1.064
A15: P15_C40 | B15: 0.991
A17: ALPHA_IND_A / f_pharm (copay_pharmacy); reference: 0%
A18: copay_pharmacy | B18: factor
A19: 0% | B19: 1
A20: 15% | B20: 0.972
A21: 25% | B21: 0.951
A23: ALPHA_IND_A / f_aml (aml); reference: {"N_BASIC": "300000", "N_BRNZ": "750000", "N_CLIN": "750000", "N_GOLD": "1250000", "N_PLAT": "2000000", "N_SILV": "1250000", "N_STD": "750000"}
A24: network | B24: aml | C24: factor
A25: N_BASIC | B25: 1250000 | C25: 1.062
A26: N_BRNZ | B26: 1250000 | C26: 1.031
A27: N_CLIN | B27: 1250000 | C27: 1.031
A28: N_GOLD | B28: 1250000 | C28: 1
A29: N_PLAT | B29: 1250000 | C29: 0.971
A30: N_SILV | B30: 1250000 | C30: 1
A31: N_STD | B31: 1250000 | C31: 1.031
A32: N_BASIC | B32: 2000000 | C32: 1.093
A33: N_BRNZ | B33: 2000000 | C33: 1.062
A34: N_CLIN | B34: 2000000 | C34: 1.062
A35: N_GOLD | B35: 2000000 | C35: 1.031
A36: N_PLAT | B36: 2000000 | C36: 1
... A52: N_STD | B52: 750000 | C52: 1
A54: ALPHA_IND_A / f_netopt (network_option); reference: OPT1
A55: plan | B55: network_option | C55: factor
A56: ANY | B56: OPT1 | C56: 1
A57: P2 | B57: OPT2 | C57: 0.88
A58: P3 | B58: OPT2 | C58: 0.905
A60: ALPHA_IND_A / f_tpa (tpa); reference: TPA_RED
A61: tpa | B61: factor
...

Sheet Add-ons
A1: Add-on modules (read only)
A3: ALPHA_IND_A / m_mat (module_maternity, PER_ELIGIBLE_FEMALE, ADD)
A4: network | B4: module_maternity | C4: expiring
A5: N_BASIC | B5: M10 | C5: 1450
A6: N_BRNZ | B6: M10 | C6: 1870
A7: N_CLIN | B7: M10 | C7: 1590
A8: N_GOLD | B8: M10 | C8: 2150
A9: N_PLAT | B9: M10 | C9: 2290
A10: N_SILV | B10: M10 | C10: 2010
A11: N_STD | B11: M10 | C11: 1730
A12: N_BASIC | B12: M20 | C12: 1830
A13: N_BRNZ | B13: M20 | C13: 2250
A14: N_CLIN | B14: M20 | C14: 1970
A15: N_GOLD | B15: M20 | C15: 2530
A16: N_PLAT | B16: M20 | C16: 2670
... A25: N_STD | B25: MAML | C25: 2490

Sheet INDIVIDUAL RGN_A
A1: INDIVIDUAL - RGN_A
A2: Base rates only (AED, NET basis, annual per member). Reference options: copay_op_diag = 0%, copay_pharmacy = 0%, ded_consult = D30, nationality = OTHER, network_option = OPT1, tpa = TPA_RED. Fill the yellow cells.
A4: TPA_RED - INDIVIDUAL RGN_A
A5: Section | B5: Age band | C5: Plan 1 (N_PLAT) | E5: Plan 2 (N_GOLD) | G5: Plan 3 (N_SILV) | I5: Plan 4 (N_BRNZ) | K5: Plan 5 (N_STD) | M5: Plan 6 (N_CLIN) | O5: Plan 7 (N_BASIC)
C6: Male | D6: Female | E6: Male | F6: Female | G6: Male | H6: Female | I6: Male | J6: Female | K6: Male | L6: Female | M6: Male | N6: Female | O6: Male | P6: Female
B7: 0-4 | C7: 1099.39 | D7: 1027.04 | E7: 965.96 | F7: 940.74 | G7: 822.35 | H7: 813.48 | I7: 738.08 | J7: 703.1 | K7: 617.18 | L7: 598.32 | M7: 507.36 | N7: 518.87 | O7: 421.86 | P7: 425.61
B8: 5-9 | C8: 1265.82 | D8: 1181.31 | E8: 1078.29 | F8: 1099.28 | G8: 936.2 | H8: 885.06 | I8: 799.18 | J8: 796.49 | K8: 692.97 | L8: 668.39 | M8: 568.74 | N8: 583.52 | O8: 511.92 | P8: 508.71
B9: 10-14 | C9: 1546.75 | D9: 1466.98 | E9: 1191.52 | F9: 1163.06 | G9: 1058.73 | H9: 1069.8 | I9: 905.57 | J9: 933.04 | K9: 802.61 | L9: 781.25 | M9: 700.69 | N9: 671.77 | O9: 559.96 | P9: 606.57
B10: 15-19 | C10: 1800.86 | D10: 1749.76 | E10: 1426.08 | F10: 1338.22 | G10: 1218.46 | H10: 1198.15 | I10: 1107.36 | J10: 1074.69 | K10: 967.83 | L10: 956.66 | M10: 811.08 | N10: 783.01 | O10: 673.09 | P10: 653.4
B11: 20-24 | C11: 1948.56 | D11: 2189.3 | E11: 1716.88 | F11: 1798.89 | G11: 1452.03 | H11: 1612.13 | I11: 1307.84 | J11: 1351.53 | K11: 1092.63 | L11: 1141.16 | M11: 925.79 | N11: 988.63 | O11: 787.33 | P11: 834.75
B12: 25-29 | C12: 2375.98 | D12: 2608.11 | E12: 1927.56 | F12: 2206.71 | G12: 1712.15 | H12: 1833.93 | I12: 1376.36 | J12: 1460.63 | K12: 1289.5 | L12: 1308.24 | M12: 1111.77 | N12: 1164.17 | O12: 931.63 | P12: 1027.91
B13: 30-34 | C13: 2719.83 | D13: 2640.25 | E13: 2183.79 | F13: 2530.03 | G13: 2126.43 | H13: 2144.82 | I13: 1668.79 | J13: 1749.15 | K13: 1488.17 | L13: 1485.84 | M13: 1215.05 | N13: 1354.13 | O13: 1076.35 | P13: 1139.7
B14: 35-39 | C14: 3243.04 | D14: 3244.97 | E14: 2562.87 | F14: 2805.87 | G14: 2324.6 | H14: 2458.34 | I14: 2079.86 | J14: 2067.11 | K14: 1722.16 | L14: 1778.63 | M14: 1468.58 | N14: 1536.92 | O14: 1224.65 | P14: 1387.86
B15: 40-44 | C15: 3575.48 | D15: 4055.79 | E15: 2981.27 | F15: 3215.53 | G15: 2748.56 | H15: 2644.54 | I15: 2147.22 | J15: 2415.94 | K15: 1967.61 | L15: 2111.12 | M15: 1654.19 | N15: 1712.01 | O15: 1456.11 | P15: 1540.93
B16: 45-49 | C16: 3982.92 | D16: 4005.61 | E16: 3659.05 | F16: 3383.41 | G16: 2931.98 | H16: 2909.78 | I16: 2546.56 | J16: 2522.15 | K16: 2272.71 | L16: 2088.5 | M16: 1868.52 | N16: 1903.18 | O16: 1657.08 | P16: 1635.88
B17: 50-54 | C17: 4470.58 | D17: 4403.61 | E17: 4058.1 | F17: 3716.2 | G17: 3478.02 | H17: 3336.41 | I17: 2855.34 | J17: 2954.36 | K17: 2509.75 | L17: 2399.1 | M17: 2150.32 | N17: 2111 | O17: 1753.9 | P17: 1738.7
B18: 55-59 | C18: 5068.71 | D18: 4792.53 | E18: 4572.68 | F18: 4493.61 | G18: 4021.15 | H18: 3571.51 | I18: 3331 | J18: 3257.49 | K18: 2783.72 | L18: 2812.56 | M18: 2356.07 | N18: 2288.29 | O18: 2023.14 | P18: 1969.08
... B20: 65-69 | C20: 6500.27 | D20: 6591.83 | E20: 5649.06 | F20: 5398.77 | G20: 4998.33 | H20: 4674.15 | I20: 4247.4 | J20: 3843.19 | K20: 3466.28 | L20: 3558.41 | M20: 2862.3 | N20: 2998.65 | O20: 2564.66 | P20: 2477.81
B21: 70+ | C21: 8006.51 | D21: 8224.94 | E21: 6588.99 | F21: 6851.46 | G21: 6111.34 | H21: 5774.3 | I21: 5095.31 | J21: 5056.74 | K21: 4317.15 | L21: 4073.51 | M21: REFER - lead reinsurer | N21: REFER - lead reinsurer | O21: REFER - lead reinsurer | P21: REFER - lead reinsurer
A24: TPA_BLUE - INDIVIDUAL RGN_A
A25: Section | B25: Age band | C25: Plan 1 (N_PLAT) | E25: Plan 2 (N_GOLD) | G25: Plan 3 (N_SILV) | I25: Plan 4 (N_BRNZ) | K25: Plan 5 (N_STD) | M25: Plan 6 (N_CLIN) | O25: Plan 7 (N_BASIC)
C26: Male | D26: Female | E26: Male | F26: Female | G26: Male | H26: Female | I26: Male | J26: Female | K26: Male | L26: Female | M26: Male | N26: Female | O26: Male | P26: Female
B27: 0-4 | C27: 1134.36 | D27: 1064.62 | E27: 937.99 | F27: 922.27 | G27: 847.53 | H27: 847.29 | I27: 710.2 | J27: 684.4 | K27: 619.14 | L27: 591.49 | M27: 494.88 | N27: 495.95 | O27: 427.11 | P27: 438.42
B28: 5-9 | C28: 1329.4 | D28: 1256.45 | E28: 1049.41 | F28: 1073.66 | G28: 919.12 | H28: 923.9 | I28: 773.43 | J28: 746 | K28: 661.06 | L28: 668.78 | M28: 581.59 | N28: 582.45 | O28: 485.8 | P28: 496.63
B29: 10-14 | C29: 1456.14 | D29: 1490.5 | E29: 1288.06 | F29: 1205.94 | G29: 1096.96 | H29: 1068.22 | I29: 939.18 | J29: 891.77 | K29: 822.29 | L29: 761.68 | M29: 647.5 | N29: 669.95 | O29: 582 | P29: 579.99
B30: 15-19 | C30: 1757.45 | D30: 1682.07 | E30: 1462.2 | F30: 1419.13 | G30: 1249.76 | H30: 1192.27 | I30: 1054.06 | J30: 1044.59 | K30: 867.61 | L30: 889.35 | M30: 776.28 | N30: 773.07 | O30: 664.2 | P30: 661.02
B31: 20-24 | C31: 2002.89 | D31: 2238.4 | E31: 1684.26 | F31: 1807.42 | G31: 1488.07 | H31: 1507.22 | I31: 1220.97 | J31: 1404.48 | K31: 1099.94 | L31: 1162.42 | M31: 961.74 | N31: 992.57 | O31: 788.15 | P31: 842
B32: 25-29 | C32: 2228.08 | D32: 2581.84 | E32: 1971.11 | F32: 2114.92 | G32: 1715.6 | H32: 1819.54 | I32: 1371.99 | J32: 1577.77 | K32: 1342.4 | L32: 1389.66 | M32: 1077.33 | N32: 1131.3 | O32: 925.61 | P32: 1000.31
B33: 30-34 | C33: 2716.04 | D33: 2986.84 | E33: 2236.15 | F33: 2536.81 | G33: 2019.13 | H33: 2116.57 | I33: 1689.46 | J33: 1841.06 | K33: 1497.35 | L33: 1570.82 | M33: 1281.83 | N33: 1442.78 | O33: 1022.2 | P33: 1081.56
B34: 35-39 | C34: 3154.16 | D34: 3271.87 | E34: 2663.19 | F34: 2707.73 | G34: 2329.16 | H34: 2576.98 | I34: 2029.47 | J34: 2036.98 | K34: 1675.84 | L34: 1855.81 | M34: 1532.01 | N34: 1513.9 | O34: 1208.09 | P34: 1368.42
B35: 40-44 | C35: 3573.16 | D35: 3748.52 | E35: 3139.4 | F35: 3101.08 | G35: 2610.14 | H35: 2929.14 | I35: 2215.61 | J35: 2468.14 | K35: 1871.78 | L35: 2123.31 | M35: 1692.82 | N35: 1870.81 | O35: 1411.6 | P35: 1505.7
B36: 45-49 | C36: 4107.76 | D36: 4116.95 | E36: 3400.75 | F36: 3357.42 | G36: 3209.59 | H36: 3013.42 | I36: 2628.55 | J36: 2459.55 | K36: 2269.33 | L36: 2075.15 | M36: 1822.75 | N36: 1797.49 | O36: 1688.59 | P36: 1580.9
B37: 50-54 | C37: 4545.33 | D37: 4484.62 | E37: 3993.34 | F37: 3954.54 | G37: 3282.33 | H37: 3471.61 | I37: 2998.7 | J37: 2775.02 | K37: 2482.03 | L37: 2470.4 | M37: 2142.77 | N37: 2104.25 | O37: 1783 | P37: 1690.07
B38: 55-59 | C38: 5639.07 | D38: 5135.43 | E38: 4473.96 | F38: 4375.28 | G38: 4035.69 | H38: 3870.21 | I38: 3194.48 | J38: 3183.38 | K38: 2837.34 | L38: 2807.35 | M38: 2394.14 | N38: 2389.57 | O38: 2087.89 | P38: 2092.58
... B40: 65-69 | C40: 6632.45 | D40: 6437.68 | E40: 5583.11 | F40: 5612.79 | G40: 5060.11 | H40: 4728.04 | I40: 4209.34 | J40: 4002.25 | K40: 3492.73 | L40: 3514 | M40: 3041.45 | N40: 2884.94 | O40: 2483.3 | P40: 2590.55
B41: 70+ | C41: 7945.17 | D41: 7673.1 | E41: 6843.72 | F41: 6832.89 | G41: 5726.17 | H41: 5955.06 | I41: 5166.44 | J41: 4780.56 | K41: 4248.21 | L41: 4239.92 | M41: REFER - lead reinsurer | N41: REFER - lead reinsurer | O41: REFER - lead reinsurer | P41: REFER - lead reinsurer
A44: TPA_GREEN - INDIVIDUAL RGN_A
A45: Section | B45: Age band | C45: Plan 1 (N_PLAT) | E45: Plan 2 (N_GOLD) | G45: Plan 3 (N_SILV) | I45: Plan 4 (N_BRNZ) | K45: Plan 5 (N_STD) | M45: Plan 6 (N_CLIN) | O45: Plan 7 (N_BASIC)
C46: Male | D46: Female | E46: Male | F46: Female | G46: Male | H46: Female | I46: Male | J46: Female | K46: Male | L46: Female | M46: Male | N46: Female | O46: Male | P46: Female
B47: 0-4 | C47: 1188.23 | D47: 1083.47 | E47: 979.24 | F47: 946.06 | G47: 791.62 | H47: 804.88 | I47: 723.34 | J47: 672.3 | K47: 626.19 | L47: 568.31 | M47: 498.23 | N47: 498.36 | O47: 451.49 | P47: 424.97
...

Sheet Terms
A1: Terms
A2: Structured terms of the submission; free text allowed in comments.
A4: Reinsurer | B4: Reinsurer X (fictional)
A5: Share by book | B5: 50%
A6: Premium basis | B6: NET
A7: Commission | B7: 15%
A8: Corridor | B8: synthetic corridor
A9: Cap | B9: synthetic cap
A10: Profit share | B10: synthetic profit_share
A11: Conditions | B11: synthetic conditions
A12: Validity | B12: 2027-12-31
A13: Comments | B13: synthetic comments

Sheet _KEYS
A1: cell_key | B1: ref | C1: kind | D1: mandatory | E1: key_json | F1: issued_sheet | G1: issued_address
A2: product_type=INDIVIDUAL|regulator=DHA|rating_region=RGN_A|tpa=TPA_RED|plan=P1|age=0-4|gender=M | B2: ='INDIVIDUAL RGN_A'!$C$7 | C2: RATE | D2: TRUE | E2: [{"age": [0, 4], "gender": "M", "plan": "P1", "product_type": "INDIVIDUAL", "rating_region": "RGN_A", "regulator": "DHA", "tpa": "TPA_RED"}] | F2: INDIVIDUAL RGN_A | G2: C7
A3: product_type=INDIVIDUAL|regulator=DHA|rating_region=RGN_A|tpa=TPA_RED|plan=P1|age=0-4|gender=F | B3: ='INDIVIDUAL RGN_A'!$D$7 | C3: RATE | D3: TRUE | E3: [{"age": [0, 4], "gender": "F", "plan": "P1", "product_type": "INDIVIDUAL", "rating_region": "RGN_A", "regulator": "DHA", "tpa": "TPA_RED"}] | F3: INDIVIDUAL RGN_A | G3: D7
A4: product_type=INDIVIDUAL|regulator=DHA|rating_region=RGN_A|tpa=TPA_RED|plan=P2|age=0-4|gender=M | B4: ='INDIVIDUAL RGN_A'!$E$7 | C4: RATE | D4: TRUE | E4: [{"age": [0, 4], "gender": "M", "plan": "P2", "product_type": "INDIVIDUAL", "rating_region": "RGN_A", "regulator": "DHA", "tpa": "TPA_RED"}] | F4: INDIVIDUAL RGN_A | G4: E7
A5: product_type=INDIVIDUAL|regulator=DHA|rating_region=RGN_A|tpa=TPA_RED|plan=P2|age=0-4|gender=F | B5: ='INDIVIDUAL RGN_A'!$F$7 | C5: RATE | D5: TRUE | E5: [{"age": [0, 4], "gender": "F", "plan": "P2", "product_type": "INDIVIDUAL", "rating_region": "RGN_A", "regulator": "DHA", "tpa": "TPA_RED"}] | F5: INDIVIDUAL RGN_A | G5: F7
A6: product_type=INDIVIDUAL|regulator=DHA|rating_region=RGN_A|tpa=TPA_RED|plan=P3|age=0-4|gender=M | B6: ='INDIVIDUAL RGN_A'!$G$7 | C6: RATE | D6: TRUE | E6: [{"age": [0, 4], "gender": "M", "plan": "P3", "product_type": "INDIVIDUAL", "rating_region": "RGN_A", "regulator": "DHA", "tpa": "TPA_RED"}] | F6: INDIVIDUAL RGN_A | G6: G7
A7: product_type=INDIVIDUAL|regulator=DHA|rating_region=RGN_A|tpa=TPA_RED|plan=P3|age=0-4|gender=F | B7: ='INDIVIDUAL RGN_A'!$H$7 | C7: RATE | D7: TRUE | E7: [{"age": [0, 4], "gender": "F", "plan": "P3", "product_type": "INDIVIDUAL", "rating_region": "RGN_A", "regulator": "DHA", "tpa": "TPA_RED"}] | F7: INDIVIDUAL RGN_A | G7: H7
A8: product_type=INDIVIDUAL|regulator=DHA|rating_region=RGN_A|tpa=TPA_RED|plan=P4|age=0-4|gender=M | B8: ='INDIVIDUAL RGN_A'!$I$7 | C8: RATE | D8: TRUE | E8: [{"age": [0, 4], "gender": "M", "plan": "P4", "product_type": "INDIVIDUAL", "rating_region": "RGN_A", "regulator": "DHA", "tpa": "TPA_RED"}] | F8: INDIVIDUAL RGN_A | G8: I7
A9: product_type=INDIVIDUAL|regulator=DHA|rating_region=RGN_A|tpa=TPA_RED|plan=P4|age=0-4|gender=F | B9: ='INDIVIDUAL RGN_A'!$J$7 | C9: RATE | D9: TRUE | E9: [{"age": [0, 4], "gender": "F", "plan": "P4", "product_type": "INDIVIDUAL", "rating_region": "RGN_A", "regulator": "DHA", "tpa": "TPA_RED"}] | F9: INDIVIDUAL RGN_A | G9: J7
A10: product_type=INDIVIDUAL|regulator=DHA|rating_region=RGN_A|tpa=TPA_RED|plan=P5|age=0-4|gender=M | B10: ='INDIVIDUAL RGN_A'!$K$7 | C10: RATE | D10: TRUE | E10: [{"age": [0, 4], "gender": "M", "plan": "P5", "product_type": "INDIVIDUAL", "rating_region": "RGN_A", "regulator": "DHA", "tpa": "TPA_RED"}] | F10: INDIVIDUAL RGN_A | G10: K7
A11: product_type=INDIVIDUAL|regulator=DHA|rating_region=RGN_A|tpa=TPA_RED|plan=P5|age=0-4|gender=F | B11: ='INDIVIDUAL RGN_A'!$L$7 | C11: RATE | D11: TRUE | E11: [{"age": [0, 4], "gender": "F", "plan": "P5", "product_type": "INDIVIDUAL", "rating_region": "RGN_A", "regulator": "DHA", "tpa": "TPA_RED"}] | F11: INDIVIDUAL RGN_A | G11: L7
A12: product_type=INDIVIDUAL|regulator=DHA|rating_region=RGN_A|tpa=TPA_RED|plan=P6|age=0-4|gender=M | B12: ='INDIVIDUAL RGN_A'!$M$7 | C12: RATE | D12: TRUE | E12: [{"age": [0, 4], "gender": "M", "plan": "P6", "product_type": "INDIVIDUAL", "rating_region": "RGN_A", "regulator": "DHA", "tpa": "TPA_RED"}] | F12: INDIVIDUAL RGN_A | G12: M7
A13: product_type=INDIVIDUAL|regulator=DHA|rating_region=RGN_A|tpa=TPA_RED|plan=P6|age=0-4|gender=F | B13: ='INDIVIDUAL RGN_A'!$N$7 | C13: RATE | D13: TRUE | E13: [{"age": [0, 4], "gender": "F", "plan": "P6", "product_type": "INDIVIDUAL", "rating_region": "RGN_A", "regulator": "DHA", "tpa": "TPA_RED"}] | F13: INDIVIDUAL RGN_A | G13: N7
A14: product_type=INDIVIDUAL|regulator=DHA|rating_region=RGN_A|tpa=TPA_RED|plan=P7|age=0-4|gender=M | B14: ='INDIVIDUAL RGN_A'!$O$7 | C14: RATE | D14: TRUE | E14: [{"age": [0, 4], "gender": "M", "plan": "P7", "product_type": "INDIVIDUAL", "rating_region": "RGN_A", "regulator": "DHA", "tpa": "TPA_RED"}] | F14: INDIVIDUAL RGN_A | G14: O7
A15: product_type=INDIVIDUAL|regulator=DHA|rating_region=RGN_A|tpa=TPA_RED|plan=P7|age=0-4|gender=F | B15: ='INDIVIDUAL RGN_A'!$P$7 | C15: RATE | D15: TRUE | E15: [{"age": [0, 4], "gender": "F", "plan": "P7", "product_type": "INDIVIDUAL", "rating_region": "RGN_A", "regulator": "DHA", "tpa": "TPA_RED"}] | F15: INDIVIDUAL RGN_A | G15: P7
A16: product_type=INDIVIDUAL|regulator=DHA|rating_region=RGN_A|tpa=TPA_RED|plan=P1|age=5-9|gender=M | B16: ='INDIVIDUAL RGN_A'!$C$8 | C16: RATE | D16: TRUE | E16: [{"age": [5, 9], "gender": "M", "plan": "P1", "product_type": "INDIVIDUAL", "rating_region": "RGN_A", "regulator": "DHA", "tpa": "TPA_RED"}] | F16: INDIVIDUAL RGN_A | G16: C8
A17: product_type=INDIVIDUAL|regulator=DHA|rating_region=RGN_A|tpa=TPA_RED|plan=P1|age=5-9|gender=F | B17: ='INDIVIDUAL RGN_A'!$D$8 | C17: RATE | D17: TRUE | E17: [{"age": [5, 9], "gender": "F", "plan": "P1", "product_type": "INDIVIDUAL", "rating_region": "RGN_A", "regulator": "DHA", "tpa": "TPA_RED"}] | F17: INDIVIDUAL RGN_A | G17: D8
A18: product_type=INDIVIDUAL|regulator=DHA|rating_region=RGN_A|tpa=TPA_RED|plan=P2|age=5-9|gender=M | B18: ='INDIVIDUAL RGN_A'!$E$8 | C18: RATE | D18: TRUE | E18: [{"age": [5, 9], "gender": "M", "plan": "P2", "product_type": "INDIVIDUAL", "rating_region": "RGN_A", "regulator": "DHA", "tpa": "TPA_RED"}] | F18: INDIVIDUAL RGN_A | G18: E8
A19: product_type=INDIVIDUAL|regulator=DHA|rating_region=RGN_A|tpa=TPA_RED|plan=P2|age=5-9|gender=F | B19: ='INDIVIDUAL RGN_A'!$F$8 | C19: RATE | D19: TRUE | E19: [{"age": [5, 9], "gender": "F", "plan": "P2", "product_type": "INDIVIDUAL", "rating_region": "RGN_A", "regulator": "DHA", "tpa": "TPA_RED"}] | F19: INDIVIDUAL RGN_A | G19: F8
A20: product_type=INDIVIDUAL|regulator=DHA|rating_region=RGN_A|tpa=TPA_RED|plan=P3|age=5-9|gender=M | B20: ='INDIVIDUAL RGN_A'!$G$8 | C20: RATE | D20: TRUE | E20: [{"age": [5, 9], "gender": "M", "plan": "P3", "product_type": "INDIVIDUAL", "rating_region": "RGN_A", "regulator": "DHA", "tpa": "TPA_RED"}] | F20: INDIVIDUAL RGN_A | G20: G8
A21: product_type=INDIVIDUAL|regulator=DHA|rating_region=RGN_A|tpa=TPA_RED|plan=P3|age=5-9|gender=F | B21: ='INDIVIDUAL RGN_A'!$H$8 | C21: RATE | D21: TRUE | E21: [{"age": [5, 9], "gender": "F", "plan": "P3", "product_type": "INDIVIDUAL", "rating_region": "RGN_A", "regulator": "DHA", "tpa": "TPA_RED"}] | F21: INDIVIDUAL RGN_A | G21: H8
A22: product_type=INDIVIDUAL|regulator=DHA|rating_region=RGN_A|tpa=TPA_RED|plan=P4|age=5-9|gender=M | B22: ='INDIVIDUAL RGN_A'!$I$8 | C22: RATE | D22: TRUE | E22: [{"age": [5, 9], "gender": "M", "plan": "P4", "product_type": "INDIVIDUAL", "rating_region": "RGN_A", "regulator": "DHA", "tpa": "TPA_RED"}] | F22: INDIVIDUAL RGN_A | G22: I8
A23: product_type=INDIVIDUAL|regulator=DHA|rating_region=RGN_A|tpa=TPA_RED|plan=P4|age=5-9|gender=F | B23: ='INDIVIDUAL RGN_A'!$J$8 | C23: RATE | D23: TRUE | E23: [{"age": [5, 9], "gender": "F", "plan": "P4", "product_type": "INDIVIDUAL", "rating_region": "RGN_A", "regulator": "DHA", "tpa": "TPA_RED"}] | F23: INDIVIDUAL RGN_A | G23: J8
A24: product_type=INDIVIDUAL|regulator=DHA|rating_region=RGN_A|tpa=TPA_RED|plan=P5|age=5-9|gender=M | B24: ='INDIVIDUAL RGN_A'!$K$8 | C24: RATE | D24: TRUE | E24: [{"age": [5, 9], "gender": "M", "plan": "P5", "product_type": "INDIVIDUAL", "rating_region": "RGN_A", "regulator": "DHA", "tpa": "TPA_RED"}] | F24: INDIVIDUAL RGN_A | G24: K8
A25: product_type=INDIVIDUAL|regulator=DHA|rating_region=RGN_A|tpa=TPA_RED|plan=P5|age=5-9|gender=F | B25: ='INDIVIDUAL RGN_A'!$L$8 | C25: RATE | D25: TRUE | E25: [{"age": [5, 9], "gender": "F", "plan": "P5", "product_type": "INDIVIDUAL", "rating_region": "RGN_A", "regulator": "DHA", "tpa": "TPA_RED"}] | F25: INDIVIDUAL RGN_A | G25: L8
A26: product_type=INDIVIDUAL|regulator=DHA|rating_region=RGN_A|tpa=TPA_RED|plan=P6|age=5-9|gender=M | B26: ='INDIVIDUAL RGN_A'!$M$8 | C26: RATE | D26: TRUE | E26: [{"age": [5, 9], "gender": "M", "plan": "P6", "product_type": "INDIVIDUAL", "rating_region": "RGN_A", "regulator": "DHA", "tpa": "TPA_RED"}] | F26: INDIVIDUAL RGN_A | G26: M8
A27: product_type=INDIVIDUAL|regulator=DHA|rating_region=RGN_A|tpa=TPA_RED|plan=P6|age=5-9|gender=F | B27: ='INDIVIDUAL RGN_A'!$N$8 | C27: RATE | D27: TRUE | E27: [{"age": [5, 9], "gender": "F", "plan": "P6", "product_type": "INDIVIDUAL", "rating_region": "RGN_A", "regulator": "DHA", "tpa": "TPA_RED"}] | F27: INDIVIDUAL RGN_A | G27: N8
A28: product_type=INDIVIDUAL|regulator=DHA|rating_region=RGN_A|tpa=TPA_RED|plan=P7|age=5-9|gender=M | B28: ='INDIVIDUAL RGN_A'!$O$8 | C28: RATE | D28: TRUE | E28: [{"age": [5, 9], "gender": "M", "plan": "P7", "product_type": "INDIVIDUAL", "rating_region": "RGN_A", "regulator": "DHA", "tpa": "TPA_RED"}] | F28: INDIVIDUAL RGN_A | G28: O8
A29: product_type=INDIVIDUAL|regulator=DHA|rating_region=RGN_A|tpa=TPA_RED|plan=P7|age=5-9|gender=F | B29: ='INDIVIDUAL RGN_A'!$P$8 | C29: RATE | D29: TRUE | E29: [{"age": [5, 9], "gender": "F", "plan": "P7", "product_type": "INDIVIDUAL", "rating_region": "RGN_A", "regulator": "DHA", "tpa": "TPA_RED"}] | F29: INDIVIDUAL RGN_A | G29: P8
A30: product_type=INDIVIDUAL|regulator=DHA|rating_region=RGN_A|tpa=TPA_RED|plan=P1|age=10-14|gender=M | B30: ='INDIVIDUAL RGN_A'!$C$9 | C30: RATE | D30: TRUE | E30: [{"age": [10, 14], "gender": "M", "plan": "P1", "product_type": "INDIVIDUAL", "rating_region": "RGN_A", "regulator": "DHA", "tpa": "TPA_RED"}] | F30: INDIVIDUAL RGN_A | G30: C9
A31: product_type=INDIVIDUAL|regulator=DHA|rating_region=RGN_A|tpa=TPA_RED|plan=P1|age=10-14|gender=F | B31: ='INDIVIDUAL RGN_A'!$D$9 | C31: RATE | D31: TRUE | E31: [{"age": [10, 14], "gender": "F", "plan": "P1", "product_type": "INDIVIDUAL", "rating_region": "RGN_A", "regulator": "DHA", "tpa": "TPA_RED"}] | F31: INDIVIDUAL RGN_A | G31: D9
A32: product_type=INDIVIDUAL|regulator=DHA|rating_region=RGN_A|tpa=TPA_RED|plan=P2|age=10-14|gender=M | B32: ='INDIVIDUAL RGN_A'!$E$9 | C32: RATE | D32: TRUE | E32: [{"age": [10, 14], "gender": "M", "plan": "P2", "product_type": "INDIVIDUAL", "rating_region": "RGN_A", "regulator": "DHA", "tpa": "TPA_RED"}] | F32: INDIVIDUAL RGN_A | G32: E9
A33: product_type=INDIVIDUAL|regulator=DHA|rating_region=RGN_A|tpa=TPA_RED|plan=P2|age=10-14|gender=F | B33: ='INDIVIDUAL RGN_A'!$F$9 | C33: RATE | D33: TRUE | E33: [{"age": [10, 14], "gender": "F", "plan": "P2", "product_type": "INDIVIDUAL", "rating_region": "RGN_A", "regulator": "DHA", "tpa": "TPA_RED"}] | F33: INDIVIDUAL RGN_A | G33: F9
A34: product_type=INDIVIDUAL|regulator=DHA|rating_region=RGN_A|tpa=TPA_RED|plan=P3|age=10-14|gender=M | B34: ='INDIVIDUAL RGN_A'!$G$9 | C34: RATE | D34: TRUE | E34: [{"age": [10, 14], "gender": "M", "plan": "P3", "product_type": "INDIVIDUAL", "rating_region": "RGN_A", "regulator": "DHA", "tpa": "TPA_RED"}] | F34: INDIVIDUAL RGN_A | G34: G9
A35: product_type=INDIVIDUAL|regulator=DHA|rating_region=RGN_A|tpa=TPA_RED|plan=P3|age=10-14|gender=F | B35: ='INDIVIDUAL RGN_A'!$H$9 | C35: RATE | D35: TRUE | E35: [{"age": [10, 14], "gender": "F", "plan": "P3", "product_type": "INDIVIDUAL", "rating_region": "RGN_A", "regulator": "DHA", "tpa": "TPA_RED"}] | F35: INDIVIDUAL RGN_A | G35: H9
A36: product_type=INDIVIDUAL|regulator=DHA|rating_region=RGN_A|tpa=TPA_RED|plan=P4|age=10-14|gender=M | B36: ='INDIVIDUAL RGN_A'!$I$9 | C36: RATE | D36: TRUE | E36: [{"age": [10, 14], "gender": "M", "plan": "P4", "product_type": "INDIVIDUAL", "rating_region": "RGN_A", "regulator": "DHA", "tpa": "TPA_RED"}] | F36: INDIVIDUAL RGN_A | G36: I9
A37: product_type=INDIVIDUAL|regulator=DHA|rating_region=RGN_A|tpa=TPA_RED|plan=P4|age=10-14|gender=F | B37: ='INDIVIDUAL RGN_A'!$J$9 | C37: RATE | D37: TRUE | E37: [{"age": [10, 14], "gender": "F", "plan": "P4", "product_type": "INDIVIDUAL", "rating_region": "RGN_A", "regulator": "DHA", "tpa": "TPA_RED"}] | F37: INDIVIDUAL RGN_A | G37: J9
A38: product_type=INDIVIDUAL|regulator=DHA|rating_region=RGN_A|tpa=TPA_RED|plan=P5|age=10-14|gender=M | B38: ='INDIVIDUAL RGN_A'!$K$9 | C38: RATE | D38: TRUE | E38: [{"age": [10, 14], "gender": "M", "plan": "P5", "product_type": "INDIVIDUAL", "rating_region": "RGN_A", "regulator": "DHA", "tpa": "TPA_RED"}] | F38: INDIVIDUAL RGN_A | G38: K9
A39: product_type=INDIVIDUAL|regulator=DHA|rating_region=RGN_A|tpa=TPA_RED|plan=P5|age=10-14|gender=F | B39: ='INDIVIDUAL RGN_A'!$L$9 | C39: RATE | D39: TRUE | E39: [{"age": [10, 14], "gender": "F", "plan": "P5", "product_type": "INDIVIDUAL", "rating_region": "RGN_A", "regulator": "DHA", "tpa": "TPA_RED"}] | F39: INDIVIDUAL RGN_A | G39: L9
A40: product_type=INDIVIDUAL|regulator=DHA|rating_region=RGN_A|tpa=TPA_RED|plan=P6|age=10-14|gender=M | B40: ='INDIVIDUAL RGN_A'!$M$9 | C40: RATE | D40: TRUE | E40: [{"age": [10, 14], "gender": "M", "plan": "P6", "product_type": "INDIVIDUAL", "rating_region": "RGN_A", "regulator": "DHA", "tpa": "TPA_RED"}] | F40: INDIVIDUAL RGN_A | G40: M9
...

Sheet _META
A1: key | B1: value
A2: tender_id | B2: T_ALPHA_2027
A3: cedant | B3: FICTIONAL_CEDANT_A
A4: structure_hash | B4: a5cc3bbbff4544408e647e19fa833066ddb52921c093d9af3d88eaa052486296
A5: spec_hash | B5: 4d971354e45b809b7311558a4b3068bde6fe30e9403d9f80b8c77ad7f7e0d769
A6: template_spec_version | B6: 1
A7: generator_version | B7: ws0-1
A8: issue_date | B8: 2026-10-24
A9: currency | B9: AED
A10: premium_basis | B10: NET
A11: allow_proposed_multipliers | B11: False
A12: n_inputs | B12: 628
A13: n_refer | B13: 12
